Workbook

Sheet ipc
A1: FUENTE: http://www.banrep.gov.co/es/ipchttps://suameca.banrep.gov.co/estadisticas-economicas/tablasPreconstruidas
A2: Año | B2: Mes | C2: Concatenado | D2: IPC BASE 2018=100 EMPALMADA | E2: Variación mensual (%) | F2: Variación año corrido (%) | G2: Variación anual (%)
A3: 1954 | B3: Julio | C3: =B3&" "&A3 -> Julio 1954 | D3: 0.026315245
A4: =A3 -> 1954 | B4: Agosto | C4: =B4&" "&A4 -> Agosto 1954 | D4: 0.026115617 | E4: -0.0076 | F4: -0.0076
A5: =A3 -> 1954 | B5: Septiembre | C5: =B5&" "&A5 -> Septiembre 1954 | D5: 0.02575894 | E5: -0.0137 | F5: -0.0212
A6: =A3 -> 1954 | B6: Octubre | C6: =B6&" "&A6 -> Octubre 1954 | D6: 0.025845492 | E6: 0.0034 | F6: -0.0179
A7: =A3 -> 1954 | B7: Noviembre | C7: =B7&" "&A7 -> Noviembre 1954 | D7: 0.025914593 | E7: 0.0027 | F7: -0.0152
A8: =A3 -> 1954 | B8: Diciembre | C8: =B8&" "&A8 -> Diciembre 1954 | D8: 0.026053495 | E8: 0.0054 | F8: -0.01
A9: 1955 | B9: Enero | C9: =B9&" "&A9 -> Enero 1955 | D9: 0.026010219 | E9: -0.0017 | F9: -0.0017
A10: =A9 -> 1955 | B10: Febrero | C10: =B10&" "&A10 -> Febrero 1955 | D10: 0.025992769 | E10: -0.0007 | F10: -0.0023
A11: =A9 -> 1955 | B11: Marzo | C11: =B11&" "&A11 -> Marzo 1955 | D11: 0.026096771 | E11: 0.004 | F11: 0.0017
A12: =A9 -> 1955 | B12: Abril | C12: =B12&" "&A12 -> Abril 1955 | D12: 0.026279647 | E12: 0.007 | F12: 0.0087
A13: =A9 -> 1955 | B13: Mayo | C13: =B13&" "&A13 -> Mayo 1955 | D13: 0.026166571 | E13: -0.0043 | F13: 0.0043
A14: =A9 -> 1955 | B14: Junio | C14: =B14&" "&A14 -> Junio 1955 | D14: 0.026148423 | E14: -0.0007 | F14: 0.0037
A15: =A9 -> 1955 | B15: Julio | C15: =B15&" "&A15 -> Julio 1955 | D15: 0.026087697 | E15: -0.0023 | F15: 0.0013 | G15: -0.0087
A16: =A9 -> 1955 | B16: Agosto | C16: =B16&" "&A16 -> Agosto 1955 | D16: 0.026113523 | E16: 0.001 | F16: 0.0023 | G16: -0.0001
A17: =A9 -> 1955 | B17: Septiembre | C17: =B17&" "&A17 -> Septiembre 1955 | D17: 0.025974621 | E17: -0.0053 | F17: -0.003 | G17: 0.0084
A18: =A9 -> 1955 | B18: Octubre | C18: =B18&" "&A18 -> Octubre 1955 | D18: 0.026043723 | E18: 0.0027 | F18: -0.0004 | G18: 0.0077
A19: =A9 -> 1955 | B19: Noviembre | C19: =B19&" "&A19 -> Noviembre 1955 | D19: 0.026287325 | E19: 0.0094 | F19: 0.009 | G19: 0.0144
A20: =A9 -> 1955 | B20: Diciembre | C20: =B20&" "&A20 -> Diciembre 1955 | D20: 0.026582578 | E20: 0.0112 | F20: 0.0203 | G20: 0.0203
A21: =A9+1 -> 1956 | B21: Enero | C21: =B21&" "&A21 -> Enero 1956 | D21: 0.026556752 | E21: -0.001 | F21: -0.001 | G21: 0.021
A22: =A10+1 -> 1956 | B22: Febrero | C22: =B22&" "&A22 -> Febrero 1956 | D22: 0.026661452 | E22: 0.0039 | F22: 0.0029 | G22: 0.0257
A23: =A11+1 -> 1956 | B23: Marzo | C23: =B23&" "&A23 -> Marzo 1956 | D23: 0.026905053 | E23: 0.0091 | F23: 0.0121 | G23: 0.031
A24: =A12+1 -> 1956 | B24: Abril | C24: =B24&" "&A24 -> Abril 1956 | D24: 0.027078855 | E24: 0.0065 | F24: 0.0186 | G24: 0.0304
A25: =A13+1 -> 1956 | B25: Mayo | C25: =B25&" "&A25 -> Mayo 1956 | D25: 0.027278483 | E25: 0.0074 | F25: 0.0262 | G25: 0.0425
A26: =A14+1 -> 1956 | B26: Junio | C26: =B26&" "&A26 -> Junio 1956 | D26: 0.02753046 | E26: 0.0092 | F26: 0.0356 | G26: 0.0528
A27: =A15+1 -> 1956 | B27: Julio | C27: =B27&" "&A27 -> Julio 1956 | D27: 0.027747538 | E27: 0.0079 | F27: 0.0438 | G27: 0.0636
A28: =A16+1 -> 1956 | B28: Agosto | C28: =B28&" "&A28 -> Agosto 1956 | D28: 0.027617012 | E28: -0.0047 | F28: 0.0389 | G28: 0.0576
A29: =A17+1 -> 1956 | B29: Septiembre | C29: =B29&" "&A29 -> Septiembre 1956 | D29: 0.027860614 | E29: 0.0088 | F29: 0.0481 | G29: 0.0726
A30: =A18+1 -> 1956 | B30: Octubre | C30: =B30&" "&A30 -> Octubre 1956 | D30: 0.028208217 | E30: 0.0125 | F30: 0.0611 | G30: 0.0831
A31: =A19+1 -> 1956 | B31: Noviembre | C31: =B31&" "&A31 -> Noviembre 1956 | D31: 0.02860817 | E31: 0.0142 | F31: 0.0762 | G31: 0.0883
A32: =A20+1 -> 1956 | B32: Diciembre | C32: =B32&" "&A32 -> Diciembre 1956 | D32: 0.028686346 | E32: 0.0027 | F32: 0.0791 | G32: 0.0791
... A118: =A106+1 -> 1964 | B118: Febrero | C118: =B118&" "&A118 -> Febrero 1964 | D118: 0.066285436 | E118: 0.0055 | F118: 0.0202 | G118: 0.2388
A119: =A107+1 -> 1964 | B119: Marzo | C119: =B119&" "&A119 -> Marzo 1964 | D119: 0.067823825 | F119: 0.0439 | G119: 0.2051
A120: =A108+1 -> 1964 | B120: Abril | C120: =B120&" "&A120 -> Abril 1964 | D120: 0.069397811 | E120: 0.0232 | F120: 0.0681 | G120: 0.1818
A121: =A109+1 -> 1964 | B121: Mayo | C121: =B121&" "&A121 -> Mayo 1964 | D121: 0.071599299 | E121: 0.0317 | F121: 0.102 | G121: 0.2043
A122: =A110+1 -> 1964 | B122: Junio | C122: =B122&" "&A122 -> Junio 1964 | D122: 0.072677707 | E122: 0.0151 | F122: 0.1186 | G122: 0.1958
A123: =A111+1 -> 1964 | B123: Julio | C123: =B123&" "&A123 -> Julio 1964 | D123: 0.072066958 | E123: -0.0084 | F123: 0.1092 | G123: 0.1767
A124: =A112+1 -> 1964 | B124: Agosto | C124: =B124&" "&A124 -> Agosto 1964 | D124: 0.070996228 | E124: -0.0149 | F124: 0.0927 | G124: 0.1563
A125: =A113+1 -> 1964 | B125: Septiembre | C125: =B125&" "&A125 -> Septiembre 1964 | D125: 0.070534851 | E125: -0.0065 | F125: 0.0856 | G125: 0.137
...

Sheet tc
A1: JUAN FELIPE DIEZ CASTAÑO | E1: CLARIDAD SAS | H1: SUPENSION PLUS | I1: IA | K1: IA
A2: https://www.youtube.com/watch?v=GxGDTbKxTc0 | E2: https://www.youtube.com/watch?v=23zZ0nepItg | K2: Periodo | L2: Entidad / Marco Legal | M2: % Aporte Total IVM | N2: % para Cálculo PPC | O2: Notas Técnicas de Colpensiones
A3: PERIODO | C3: % | E3: 1980 | K3: 1946 - 1966 | L3: Cajas Públicas / Ley 90/46 | M3: 5.0% - 10.0% | N3: 0.04545 | O3: Se aplica el factor de proporcionalidad del 45.45% sobre el descuento global de la época [cite: 8, 26, 177].
A4: 16803 | B4: 24472 | C4: 0.0455 | E4: 1981 | I4: 0.0455 | K4: 1967 - 1984 | L4: ISS (Acuerdo 224/66) | M4: 0.06 | N4: 4.5% - 6.0% | O4: El aporte estatal del 1.5% a menudo no se dio; Colpensiones liquida sobre el porcentaje efectivamente cotizado [cite: 17, 117].
A5: 24473 | B5: 26298 | C5: 0.045 | E5: 1982 | K5: 1985 - 1993 | L5: ISS (Acuerdo 049/90) | M5: 0.065 | N5: 0.065 | O5: Tasa estable previa a la Ley 100 [cite: 117, 120].
A6: 26299 | B6: 28156 | C6: 0.06755 | E6: 1983 | K6: 1994 (Abr - Dic) | L6: Ley 100 / Art. 20 | M6: 0.115 | N6: 0.115 | O6: Incluye 8% de pensión y 3.5% de administración/seguros [cite: 7, 47].
A7: 28157 | B7: 30010 | C7: 0.09 | E7: 1984 | H7: 0.1125 | K7: 1995 | L7: Ley 100 / Art. 20 | M7: 0.125 | N7: 0.125 | O7: Incluye 9% de pensión y 3.5% de administración/seguros [cite: 7, 47].
A8: 30011 | B8: 31320 | C8: 0.1125 | E8: 1985 | H8: 0.065 | K8: 1996 - 2002 | L8: Ley 100 / Art. 20 | M8: 0.135 | N8: 0.135 | O8: Incluye 10% de pensión y 3.5% de administración/seguros [cite: 7, 47].
A9: 31321 | B9: 34334 | C9: 0.065 | E9: 1986 | I9: 0.065 | K9: 2003 | L9: Ley 797 / Art. 7 | M9: 0.135 | N9: 0.135 | O9: Tasa plena unificada por reforma pensional [cite: 7, 18, 47].
A10: 34335 | B10: 34699 | C10: 0.115 | E10: 1987 | I10: 0.115 | K10: 2004 | L10: Ley 797 / Art. 7 | M10: 0.145 | N10: 0.145 | O10: Incremento de 1 punto porcentual [cite: 7, 47].
A11: 34700 | B11: 35064 | C11: 0.125 | E11: 1988 | I11: 0.125 | K11: 2005 | L11: Ley 797 / Art. 7 | M11: 0.15 | N11: 0.15 | O11: Incremento de 0.5 puntos porcentuales [cite: 7, 47].
A12: 35065 | B12: 37986 | C12: 0.135 | E12: 1989 | H12: 0.065 | K12: 2006 - 2007 | L12: Ley 797 / Art. 7 | M12: 0.155 | N12: 0.155 | O12: Incremento de 0.5 puntos porcentuales [cite: 7, 47].
A13: 37987 | B13: 38352 | C13: 0.145 | E13: 1990 | F13: 0.065 | K13: 2008 - 2024 | L13: Ley 797 / Art. 7 | M13: 0.16 | N13: 0.16 | O13: Tasa vigente actual. Incluye administración y seguros [cite: 7, 19, 47].
A14: 38353 | B14: 38717 | C14: 0.15 | E14: 1991 | F14: 0.065 | K14: 2025 - 2026 | L14: Ley 2381 de 2024 | M14: 0.16 | N14: 0.16 | O14: Se mantiene la tasa total de aporte en el nuevo sistema de pilares [cite: 25, 27, 132].
A15: 38718 | B15: 39447 | C15: 0.155 | E15: 1992 | F15: 0.065
A16: 39448 | B16: 46387 | C16: 0.16 | E16: 1993 | F16: 0.065 | H16: 0.08
E17: 1994 | F17: 0.1151 | H17: 0.125
E18: 1995 | H18: 0.125
E19: 1996 | H19: 0.135 | I19: 0.135
E20: 1997 | F20: 0.1351 | I20: 0.135
E21: 1998 | F21: 0.1351 | I21: 0.135
E22: 1999 | I22: 0.135
E23: 2000 | I23: 0.135
E24: 2001 | I24: 0.135
E25: 2002 | I25: 0.135
E26: 2003 | I26: 0.135
E27: 2004 | F27: 0.1451 | I27: 0.145
E28: 2005
E29: 2006
E30: 2007 | H30: 0.155
E31: 2008 | I31: 0.16
E32: 2009 | I32: 0.16
E33: 2010 | I33: 0.16
E34: 2011 | H34: 0.16 | I34: 0.16
E35: 2012 | I35: 0.16
E36: 2013 | I36: 0.16
E37: 2014 | I37: 0.16
E38: 2015 | I38: 0.16
E39: 2016 | I39: 0.16
E40: 2017 | I40: 0.16
...

Sheet smlv
A1: AÑO | B1: SMLV | C1: AUX TRANSPORTE | D1: SALARIO BASE | E1: NORMA smlv | F1: Norma Aux. Tpte
A2: 1950 | B2: 60 | C2: 0 | D2: =Table10[[#This Row],[AUX TRANSPORTE]]+Table10[[#This Row],[SMLV]] -> 60 | E2: - | F2: -
A3: 1951 | B3: 60 | C3: 0 | D3: =Table10[[#This Row],[AUX TRANSPORTE]]+Table10[[#This Row],[SMLV]] -> 60 | E3: - | F3: -
A4: 1952 | B4: 60 | C4: 0 | D4: =Table10[[#This Row],[AUX TRANSPORTE]]+Table10[[#This Row],[SMLV]] -> 60 | E4: - | F4: -
A5: 1953 | B5: 60 | C5: 0 | D5: =Table10[[#This Row],[AUX TRANSPORTE]]+Table10[[#This Row],[SMLV]] -> 60 | E5: - | F5: -
A6: 1954 | B6: 60 | C6: 0 | D6: =Table10[[#This Row],[AUX TRANSPORTE]]+Table10[[#This Row],[SMLV]] -> 60 | E6: - | F6: -
A7: 1955 | B7: 60 | C7: 0 | D7: =Table10[[#This Row],[AUX TRANSPORTE]]+Table10[[#This Row],[SMLV]] -> 60 | E7: D.3781/49 | F7: -
A8: 1956 | B8: 135 | C8: 0 | D8: =Table10[[#This Row],[AUX TRANSPORTE]]+Table10[[#This Row],[SMLV]] -> 135 | E8: D.2214/56 | F8: -
A9: 1957 | B9: 155 | C9: 0 | D9: =Table10[[#This Row],[AUX TRANSPORTE]]+Table10[[#This Row],[SMLV]] -> 155 | E9: D.2214/56 | F9: -
A10: 1958 | B10: 155 | C10: 0 | D10: =Table10[[#This Row],[AUX TRANSPORTE]]+Table10[[#This Row],[SMLV]] -> 155 | E10: D.2214/56 | F10: -
A11: 1959 | B11: 155 | C11: 0 | D11: =Table10[[#This Row],[AUX TRANSPORTE]]+Table10[[#This Row],[SMLV]] -> 155 | E11: D.2214/56 | F11: -
A12: 1960 | B12: 189 | C12: 0 | D12: =Table10[[#This Row],[AUX TRANSPORTE]]+Table10[[#This Row],[SMLV]] -> 189 | E12: D.1090/60 | F12: -
A13: 1961 | B13: 189 | C13: 0 | D13: =Table10[[#This Row],[AUX TRANSPORTE]]+Table10[[#This Row],[SMLV]] -> 189 | E13: D.1090/60 | F13: -
... A71: 2019 | B71: 828116 | C71: 97032 | D71: =Table10[[#This Row],[AUX TRANSPORTE]]+Table10[[#This Row],[SMLV]] -> 925148 | E71: - | F71: -
A72: 2020 | B72: 877803 | C72: 102854 | D72: =Table10[[#This Row],[AUX TRANSPORTE]]+Table10[[#This Row],[SMLV]] -> 980657 | E72: 2360 de dic 26 de 2019
A73: 2021 | B73: 908526 | C73: 106454 | D73: =Table10[[#This Row],[AUX TRANSPORTE]]+Table10[[#This Row],[SMLV]] -> 1014980 | E73: 1786 de dic 29 de 2020
A74: 2022 | B74: 1000000 | C74: 117172 | D74: =Table10[[#This Row],[AUX TRANSPORTE]]+Table10[[#This Row],[SMLV]] -> 1117172 | E74: 1724 de dic 15 de 2021
A75: 2023 | B75: 1160000 | C75: 140606 | D75: =Table10[[#This Row],[AUX TRANSPORTE]]+Table10[[#This Row],[SMLV]] -> 1300606 | E75: 2623 de dic 28 2022
A76: 2024 | B76: 1300000 | C76: 162000 | D76: =Table10[[#This Row],[AUX TRANSPORTE]]+Table10[[#This Row],[SMLV]] -> 1462000 | E76: 2292 de dic 29 2023
A77: 2025 | B77: 1423500 | C77: 200000 | D77: =Table10[[#This Row],[AUX TRANSPORTE]]+Table10[[#This Row],[SMLV]] -> 1623500 | E77: 1572 de dic 24 de 2024
A78: 2026 | B78: 1750905 | C78: 249095 | D78: =Table10[[#This Row],[AUX TRANSPORTE]]+Table10[[#This Row],[SMLV]] -> 2000000 | E78: Decreto 0159 del 19 de febrero de 2026

Sheet Indemnizacion_sustitutiva
A1: CLIENTE | F1: ISP = SBC x SC x PPC
A2: CEDULA | F2: SBC: SALARIO BASE DE COTIZACION SEMANAL | H2: =(SUMPRODUCT(O11:O1000,I11:I1000)/SUM(I11:I1000))*(7/30) -> 199739.74
A3: FECHA DE NACIMIENTO | F3: SC: SEMANAS COTIZADAS | H3: =SUM(H11:H1000) -> 268
A4: MES FINAL EN EL QUE SE LIQUIDARA | B4: Diciembre | F4: PPC: PORCENTAJES PONDERADO DE PORCENTAJES DE COTIZACION | H4: =SUMPRODUCT(I11:I1000,J11:J1000)/SUM(I11:I1000) -> 0.083534115
A5: AÑO EN EL QUE SE LIQUIDARA | B5: 2023 | F5: ISP: INDEMNIZACION SUSTITUTIVA DE PESNIÓN | H5: =H4*H3*H2 -> 4471602.1
A10: [1]Identificación Aportante | B10: [2]Nombre o Razón Social | C10: mes | D10: Año | E10: [3]Desde | F10: [4]Hasta | G10: [5]Salario (IBC) | H10: [6]Semanas | I10: [7] No. Dias | J10: [8] Porcentaje de cotizaciòn | K10: Fecha IPC Final | L10: [9] IPC final | M10: Fecha IPC Inicial | N10: [10] IPC inicial | O10: [11] IBC Indexado [5]x[9]/[10]
C11: =IF(MONTH(E11)=MONTH(F11), PROPER(TEXT(E11, "mmmm")), "Rev") -> Febrero | D11: =IF(YEAR(E11)=YEAR(F11), YEAR(E11), "Rev") -> 1990 | E11: 32911 | F11: 32932 | G11: 47370 | H11: =I11/7 -> 3.1428571 | I11: =IF(AND(DAY(E11)=1, OR(F11=EOMONTH(F11,0), AND(MONTH(F11)=2, DAY(F11)>=28))), 30, F11 - E11 + 1) -> 22 | J11: {=INDEX(tc!$C$4:$C$15, MATCH(1, INDEX((tc!$A$4:$A$15<=E11)*(tc!$B$4:$B$15>=E11), 0), 0))} -> 0.065 | K11: =CONCATENATE($B$4," ",$B$5) -> Diciembre 2023 | L11: =VLOOKUP(K11,ipc!$C$2:$D$1048576,2,0) -> 137.71611 | M11: =C11&" "&D11 -> Febrero 1990 | N11: =VLOOKUP(M11,ipc!$C$2:$D$1048576,2,0) -> 6.1899122 | O11: =G11*(L11/N11) -> 1053910.3
C12: =IF(MONTH(E12)=MONTH(F12), PROPER(TEXT(E12, "mmmm")), "Rev") -> Marzo | D12: =IF(YEAR(E12)=YEAR(F12), YEAR(E12), "Rev") -> 1990 | E12: 32933 | F12: 32963 | G12: 47370 | H12: =I12/7 -> 4.2857143 | I12: =IF(AND(DAY(E12)=1, OR(F12=EOMONTH(F12,0), AND(MONTH(F12)=2, DAY(F12)>=28))), 30, F12 - E12 + 1) -> 30 | J12: {=INDEX(tc!$C$4:$C$15, MATCH(1, INDEX((tc!$A$4:$A$15<=E12)*(tc!$B$4:$B$15>=E12), 0), 0))} -> 0.065 | K12: =CONCATENATE($B$4," ",$B$5) -> Diciembre 2023 | L12: =VLOOKUP(K12,ipc!$C$2:$D$1048576,2,0) -> 137.71611 | M12: =C12&" "&D12 -> Marzo 1990 | N12: =VLOOKUP(M12,ipc!$C$2:$D$1048576,2,0) -> 6.3693879 | O12: =G12*(L12/N12) -> 1024213.4
C13: =IF(MONTH(E13)=MONTH(F13), PROPER(TEXT(E13, "mmmm")), "Rev") -> Abril | D13: =IF(YEAR(E13)=YEAR(F13), YEAR(E13), "Rev") -> 1990 | E13: 32964 | F13: 32993 | G13: 47370 | H13: =I13/7 -> 4.2857143 | I13: =IF(AND(DAY(E13)=1, OR(F13=EOMONTH(F13,0), AND(MONTH(F13)=2, DAY(F13)>=28))), 30, F13 - E13 + 1) -> 30 | J13: {=INDEX(tc!$C$4:$C$15, MATCH(1, INDEX((tc!$A$4:$A$15<=E13)*(tc!$B$4:$B$15>=E13), 0), 0))} -> 0.065 | K13: =CONCATENATE($B$4," ",$B$5) -> Diciembre 2023 | L13: =VLOOKUP(K13,ipc!$C$2:$D$1048576,2,0) -> 137.71611 | M13: =C13&" "&D13 -> Abril 1990 | N13: =VLOOKUP(M13,ipc!$C$2:$D$1048576,2,0) -> 6.5485836 | O13: =G13*(L13/N13) -> 996186.73
C14: =IF(MONTH(E14)=MONTH(F14), PROPER(TEXT(E14, "mmmm")), "Rev") -> Mayo | D14: =IF(YEAR(E14)=YEAR(F14), YEAR(E14), "Rev") -> 1990 | E14: 32994 | F14: 33024 | G14: 47370 | H14: =I14/7 -> 4.2857143 | I14: =IF(AND(DAY(E14)=1, OR(F14=EOMONTH(F14,0), AND(MONTH(F14)=2, DAY(F14)>=28))), 30, F14 - E14 + 1) -> 30 | J14: {=INDEX(tc!$C$4:$C$15, MATCH(1, INDEX((tc!$A$4:$A$15<=E14)*(tc!$B$4:$B$15>=E14), 0), 0))} -> 0.065 | K14: =CONCATENATE($B$4," ",$B$5) -> Diciembre 2023 | L14: =VLOOKUP(K14,ipc!$C$2:$D$1048576,2,0) -> 137.71611 | M14: =C14&" "&D14 -> Mayo 1990 | N14: =VLOOKUP(M14,ipc!$C$2:$D$1048576,2,0) -> 6.6765673 | O14: =G14*(L14/N14) -> 977090.75
C15: =IF(MONTH(E15)=MONTH(F15), PROPER(TEXT(E15, "mmmm")), "Rev") -> Junio | D15: =IF(YEAR(E15)=YEAR(F15), YEAR(E15), "Rev") -> 1990 | E15: 33025 | F15: 33054 | G15: 47370 | H15: =I15/7 -> 4.2857143 | I15: =IF(AND(DAY(E15)=1, OR(F15=EOMONTH(F15,0), AND(MONTH(F15)=2, DAY(F15)>=28))), 30, F15 - E15 + 1) -> 30 | J15: {=INDEX(tc!$C$4:$C$15, MATCH(1, INDEX((tc!$A$4:$A$15<=E15)*(tc!$B$4:$B$15>=E15), 0), 0))} -> 0.065 | K15: =CONCATENATE($B$4," ",$B$5) -> Diciembre 2023 | L15: =VLOOKUP(K15,ipc!$C$2:$D$1048576,2,0) -> 137.71611 | M15: =C15&" "&D15 -> Junio 1990 | N15: =VLOOKUP(M15,ipc!$C$2:$D$1048576,2,0) -> 6.8071265 | O15: =G15*(L15/N15) -> 958350.36
C16: =IF(MONTH(E16)=MONTH(F16), PROPER(TEXT(E16, "mmmm")), "Rev") -> Julio | D16: =IF(YEAR(E16)=YEAR(F16), YEAR(E16), "Rev") -> 1990 | E16: 33055 | F16: 33085 | G16: 47370 | H16: =I16/7 -> 4.2857143 | I16: =IF(AND(DAY(E16)=1, OR(F16=EOMONTH(F16,0), AND(MONTH(F16)=2, DAY(F16)>=28))), 30, F16 - E16 + 1) -> 30 | J16: {=INDEX(tc!$C$4:$C$15, MATCH(1, INDEX((tc!$A$4:$A$15<=E16)*(tc!$B$4:$B$15>=E16), 0), 0))} -> 0.065 | K16: =CONCATENATE($B$4," ",$B$5) -> Diciembre 2023 | L16: =VLOOKUP(K16,ipc!$C$2:$D$1048576,2,0) -> 137.71611 | M16: =C16&" "&D16 -> Julio 1990 | N16: =VLOOKUP(M16,ipc!$C$2:$D$1048576,2,0) -> 6.8994647 | O16: =G16*(L16/N16) -> 945524.38
C17: =IF(MONTH(E17)=MONTH(F17), PROPER(TEXT(E17, "mmmm")), "Rev") -> Agosto | D17: =IF(YEAR(E17)=YEAR(F17), YEAR(E17), "Rev") -> 1990 | E17: 33086 | F17: 33116 | G17: 47370 | H17: =I17/7 -> 4.2857143 | I17: =IF(AND(DAY(E17)=1, OR(F17=EOMONTH(F17,0), AND(MONTH(F17)=2, DAY(F17)>=28))), 30, F17 - E17 + 1) -> 30 | J17: {=INDEX(tc!$C$4:$C$15, MATCH(1, INDEX((tc!$A$4:$A$15<=E17)*(tc!$B$4:$B$15>=E17), 0), 0))} -> 0.065 | K17: =CONCATENATE($B$4," ",$B$5) -> Diciembre 2023 | L17: =VLOOKUP(K17,ipc!$C$2:$D$1048576,2,0) -> 137.71611 | M17: =C17&" "&D17 -> Agosto 1990 | N17: =VLOOKUP(M17,ipc!$C$2:$D$1048576,2,0) -> 7.008943 | O17: =G17*(L17/N17) -> 930755.48
C18: =IF(MONTH(E18)=MONTH(F18), PROPER(TEXT(E18, "mmmm")), "Rev") -> Septiembre | D18: =IF(YEAR(E18)=YEAR(F18), YEAR(E18), "Rev") -> 1990 | E18: 33117 | F18: 33146 | G18: 47370 | H18: =I18/7 -> 4.2857143 | I18: =IF(AND(DAY(E18)=1, OR(F18=EOMONTH(F18,0), AND(MONTH(F18)=2, DAY(F18)>=28))), 30, F18 - E18 + 1) -> 30 | J18: {=INDEX(tc!$C$4:$C$15, MATCH(1, INDEX((tc!$A$4:$A$15<=E18)*(tc!$B$4:$B$15>=E18), 0), 0))} -> 0.065 | K18: =CONCATENATE($B$4," ",$B$5) -> Diciembre 2023 | L18: =VLOOKUP(K18,ipc!$C$2:$D$1048576,2,0) -> 137.71611 | M18: =C18&" "&D18 -> Septiembre 1990 | N18: =VLOOKUP(M18,ipc!$C$2:$D$1048576,2,0) -> 7.1757061 | O18: =G18*(L18/N18) -> 909124.77
C19: =IF(MONTH(E19)=MONTH(F19), PROPER(TEXT(E19, "mmmm")), "Rev") -> Octubre | D19: =IF(YEAR(E19)=YEAR(F19), YEAR(E19), "Rev") -> 1990 | E19: 33147 | F19: 33177 | G19: 47370 | H19: =I19/7 -> 4.2857143 | I19: =IF(AND(DAY(E19)=1, OR(F19=EOMONTH(F19,0), AND(MONTH(F19)=2, DAY(F19)>=28))), 30, F19 - E19 + 1) -> 30 | J19: {=INDEX(tc!$C$4:$C$15, MATCH(1, INDEX((tc!$A$4:$A$15<=E19)*(tc!$B$4:$B$15>=E19), 0), 0))} -> 0.065 | K19: =CONCATENATE($B$4," ",$B$5) -> Diciembre 2023 | L19: =VLOOKUP(K19,ipc!$C$2:$D$1048576,2,0) -> 137.71611 | M19: =C19&" "&D19 -> Octubre 1990 | N19: =VLOOKUP(M19,ipc!$C$2:$D$1048576,2,0) -> 7.3139503 | O19: =G19*(L19/N19) -> 891941
C20: =IF(MONTH(E20)=MONTH(F20), PROPER(TEXT(E20, "mmmm")), "Rev") -> Noviembre | D20: =IF(YEAR(E20)=YEAR(F20), YEAR(E20), "Rev") -> 1990 | E20: 33178 | F20: 33207 | G20: 47370 | H20: =I20/7 -> 4.2857143 | I20: =IF(AND(DAY(E20)=1, OR(F20=EOMONTH(F20,0), AND(MONTH(F20)=2, DAY(F20)>=28))), 30, F20 - E20 + 1) -> 30 | J20: {=INDEX(tc!$C$4:$C$15, MATCH(1, INDEX((tc!$A$4:$A$15<=E20)*(tc!$B$4:$B$15>=E20), 0), 0))} -> 0.065 | K20: =CONCATENATE($B$4," ",$B$5) -> Diciembre 2023 | L20: =VLOOKUP(K20,ipc!$C$2:$D$1048576,2,0) -> 137.71611 | M20: =C20&" "&D20 -> Noviembre 1990 | N20: =VLOOKUP(M20,ipc!$C$2:$D$1048576,2,0) -> 7.4625653 | O20: =G20*(L20/N20) -> 874178.23
C21: =IF(MONTH(E21)=MONTH(F21), PROPER(TEXT(E21, "mmmm")), "Rev") -> Diciembre | D21: =IF(YEAR(E21)=YEAR(F21), YEAR(E21), "Rev") -> 1990 | E21: 33208 | F21: 33238 | G21: 47370 | H21: =I21/7 -> 4.2857143 | I21: =IF(AND(DAY(E21)=1, OR(F21=EOMONTH(F21,0), AND(MONTH(F21)=2, DAY(F21)>=28))), 30, F21 - E21 + 1) -> 30 | J21: {=INDEX(tc!$C$4:$C$15, MATCH(1, INDEX((tc!$A$4:$A$15<=E21)*(tc!$B$4:$B$15>=E21), 0), 0))} -> 0.065 | K21: =CONCATENATE($B$4," ",$B$5) -> Diciembre 2023 | L21: =VLOOKUP(K21,ipc!$C$2:$D$1048576,2,0) -> 137.71611 | M21: =C21&" "&D21 -> Diciembre 1990 | N21: =VLOOKUP(M21,ipc!$C$2:$D$1048576,2,0) -> 7.6507758 | O21: =G21*(L21/N21) -> 852673.29
C22: =IF(MONTH(E22)=MONTH(F22), PROPER(TEXT(E22, "mmmm")), "Rev") -> Enero | D22: =IF(YEAR(E22)=YEAR(F22), YEAR(E22), "Rev") -> 1991 | E22: 33239 | F22: 33269 | G22: 54630 | H22: =I22/7 -> 4.2857143 | I22: =IF(AND(DAY(E22)=1, OR(F22=EOMONTH(F22,0), AND(MONTH(F22)=2, DAY(F22)>=28))), 30, F22 - E22 + 1) -> 30 | J22: {=INDEX(tc!$C$4:$C$15, MATCH(1, INDEX((tc!$A$4:$A$15<=E22)*(tc!$B$4:$B$15>=E22), 0), 0))} -> 0.065 | K22: =CONCATENATE($B$4," ",$B$5) -> Diciembre 2023 | L22: =VLOOKUP(K22,ipc!$C$2:$D$1048576,2,0) -> 137.71611 | M22: =C22&" "&D22 -> Enero 1991 | N22: =VLOOKUP(M22,ipc!$C$2:$D$1048576,2,0) -> 7.8805883 | O22: =G22*(L22/N22) -> 954678.86
... C76: =IF(MONTH(E76)=MONTH(F76), PROPER(TEXT(E76, "mmmm")), "Rev") -> Mayo | D76: =IF(YEAR(E76)=YEAR(F76), YEAR(E76), "Rev") -> 2004 | E76: 38108 | F76: 38110 | G76: 35800 | H76: =I76/7 -> 0.42857143 | I76: =IF(AND(DAY(E76)=1, OR(F76=EOMONTH(F76,0), AND(MONTH(F76)=2, DAY(F76)>=28))), 30, F76 - E76 + 1) -> 3 | J76: {=INDEX(tc!$C$4:$C$15, MATCH(1, INDEX((tc!$A$4:$A$15<=E76)*(tc!$B$4:$B$15>=E76), 0), 0))} -> 0.145 | K76: =CONCATENATE($B$4," ",$B$5) -> Diciembre 2023 | L76: =VLOOKUP(K76,ipc!$C$2:$D$1048576,2,0) -> 137.71611 | M76: =C76&" "&D76 -> Mayo 2004 | N76: =VLOOKUP(M76,ipc!$C$2:$D$1048576,2,0) -> 55.172833 | O76: =G76*(L76/N76) -> 89359.861
